Workbook

Sheet Income Statement
A1: Particulars | B1: FY23(Year ended 31-Mar-2023 ) | C1: FY24 (Year ended 31-Mar-2024) | D1: FY25 (Year ended 31-Mar-2025)
A2: Revenue from operations | B2: 41833.25 | C2: 49532.95 | D2: 57789.81 | F2: revenue from operaton
A3: Other income | B3: 163.09 | C3: 189.05 | D3: 174.02 | F3: other income
A4: Total income | B4: 41996.34 | C4: 49722 | D4: 57963.83 | F4: total income
A5: Purchases of stock-in-trade | B5: 36243.89 | C5: 43214.52 | D5: 50698.32 | F5: cogs
A6: Change in inventories of stock-in-trade | B6: -468.67 | C6: -667.87 | D6: -1082.02
A7: Employee benefits expense | B7: 648.18 | C7: 785.71 | D7: 1013.26
A8: Finance costs | B8: 48.07 | C8: 44.27 | D8: 57.75
A9: Depreciation and amortisation expense | B9: 543.25 | C9: 632.79 | D9: 775.82
A10: Other expenses | B10: 1750.46 | C10: 2101.2 | D10: 2617.53
A11: Total expenses | B11: 38765.18 | C11: 46110.62 | D11: 54080.66
A12: Profit before tax | B12: 3231.16 | C12: 3611.38 | D12: 3883.17
A13: Current tax | B13: 799.88 | C13: 901 | D13: 970.89
A14: Deferred tax charge | B14: 13.66 | C14: 15.54 | D14: 21.11
A15: Tax in respect of earlier period/year | B15: -138.78 | C15: -0.08 | D15: -36.01
A16: Net profit after tax | B16: 2556.4 | C16: 2694.92 | D16: 2927.18
A17: Other comprehensive profit/(loss) (net of tax) | B17: -4.22 | C17: -7.6 | D17: -7.33
... A22: EPS Diluted (₹) | B22: 39.22 | C22: 41.36 | D22: 44.87

Sheet P&L Assumptions
G1: Scenarios
G2: Case 1 | H2: Optimistic case
A3: selected scenario | C3: 1 | G3: Case 2 | H3: Base case
G4: Case 3 | H4: Worst cae
C6: FY23 | D6: FY24 | E6: FY25 | F6: FY26 FORECAST | G6: FY27 FORECAST | H6: FY28 FORECAST | I6: FY29 FORECAST
A8: Revenues | C8: 41833.25 | D8: 49532.95 | E8: 57789.81 | F8: =E8*(1+F9) -> 68769.874 | G8: =F8*(1+G9) -> 81148.451 | H8: =G8*(1+H9) -> 94943.688 | I8: =H8*(1+I9) -> 110134.68
A9: y-o-y growth% | D9: =D8/C8-1 -> 0.18405694 | E9: =E8/D8-1 -> 0.16669429 | F9: =CHOOSE($C$3,F10,F11,F12) -> 0.19 | G9: =CHOOSE($C$3,G10,G11,G12) -> 0.18 | H9: =CHOOSE($C$3,H10,H11,H12) -> 0.17 | I9: =CHOOSE($C$3,I10,I11,I12) -> 0.16
A10: Case 1 | F10: 0.19 | G10: 0.18 | H10: 0.17 | I10: 0.16
A11: Case 2 | F11: 0.17 | G11: 0.16 | H11: 0.15 | I11: 0.14
A12: Case 3 | F12: 0.15 | G12: 0.14 | H12: 0.13 | I12: 0.12
A14: Other Income | C14: 163.09 | D14: 189.05 | E14: 174.02 | F14: =E14*(1+F15) -> 174.02 | G14: =F14*(1+G15) -> 174.02 | H14: =G14*(1+H15) -> 174.02 | I14: =H14*(1+I15) -> 174.02
A15: y-o-y growth% | F15: =CHOOSE($C$3,F16,F17,F18) -> 0 | G15: =CHOOSE($C$3,G16,G17,G18) -> 0 | H15: =CHOOSE($C$3,H16,H17,H18) -> 0 | I15: =CHOOSE($C$3,I16,I17,I18) -> 0
A16: Case 1 | F16: 0 | G16: 0 | H16: 0 | I16: 0
A17: Case 2 | F17: 0 | G17: 0 | H17: 0 | I17: 0
A18: Case 3 | F18: 0 | G18: 0 | H18: 0 | I18: 0
A20: Cost of Goods Sold | C20: 35775.22 | D20: 42546.65 | E20: 49616.3 | F20: =F8*F21 -> 58798.242 | G20: =G8*G21 -> 69381.926 | H20: =H8*H21 -> 81176.853 | I20: =I8*I21 -> 94165.15
A21: % of revenue | C21: =C20/C$8 -> 0.85518625 | D21: =D20/D$8 -> 0.85895651 | E21: =E20/E8 -> 0.85856486 | F21: =CHOOSE($C$3,F22,F23,F24) -> 0.855 | G21: =CHOOSE($C$3,G22,G23,G24) -> 0.855 | H21: =CHOOSE($C$3,H22,H23,H24) -> 0.855 | I21: =CHOOSE($C$3,I22,I23,I24) -> 0.855
A22: Case 1 | F22: 0.855 | G22: 0.855 | H22: 0.855 | I22: 0.855
A23: Case 2 | F23: 0.859 | G23: 0.859 | H23: 0.859 | I23: 0.859
A24: Case 3 | F24: 0.87 | G24: 0.87 | H24: 0.87 | I24: 0.87
A26: Empolyee expenses | C26: 648.18 | D26: 785.71 | E26: 1013.26 | F26: =F8*F27 -> 1237.8577 | G26: =G8*G27 -> 1460.6721 | H26: =H8*H27 -> 1708.9864 | I26: =I8*I27 -> 1982.4242
A27: % of revenue | C27: =C26/C$8 -> 0.015494373 | D27: =D26/D$8 -> 0.01586237 | E27: =E26/E$8 -> 0.017533541 | F27: =CHOOSE($C$3,F28,F29,F30) -> 0.018 | G27: =CHOOSE($C$3,G28,G29,G30) -> 0.018 | H27: =CHOOSE($C$3,H28,H29,H30) -> 0.018 | I27: =CHOOSE($C$3,I28,I29,I30) -> 0.018
A28: Case 1 | F28: 0.018 | G28: 0.018 | H28: 0.018 | I28: 0.018
A29: Case 2 | F29: 0.02 | G29: 0.02 | H29: 0.02 | I29: 0.02
A30: Case 3 | F30: 0.023 | G30: 0.023 | H30: 0.023 | I30: 0.023
A32: Finance costs | C32: 48.07 | D32: 44.27 | E32: 57.75 | F32: =F8*F33 -> 55.015899 | G32: =G8*G33 -> 64.918761 | H32: =H8*H33 -> 75.95495 | I32: =I8*I33 -> 88.107742
A33: % of revenue | C33: =C32/C$8 -> 0.001149086 | D33: =D32/D$8 -> 0.0008937485 | E33: =E32/E$8 -> 0.00099931112 | F33: =CHOOSE($C$3,F34,F35,F36) -> 0.0008 | G33: =CHOOSE($C$3,G34,G35,G36) -> 0.0008 | H33: =CHOOSE($C$3,H34,H35,H36) -> 0.0008 | I33: =CHOOSE($C$3,I34,I35,I36) -> 0.0008
A34: Case 1 | F34: 0.0008 | G34: 0.0008 | H34: 0.0008 | I34: 0.0008
A35: Case 2 | F35: 0.001 | G35: 0.001 | H35: 0.001 | I35: 0.001
A36: Case 3 | F36: 0.0012 | G36: 0.0012 | H36: 0.0012 | I36: 0.0012
A38: D & A | C38: 543.25 | D38: 632.79 | E38: 775.82 | F38: =F8*F39 -> 894.00836 | G38: =G8*G39 -> 1054.9299 | H38: =H8*H39 -> 1234.2679 | I38: =I8*I39 -> 1431.7508
A39: % of revenues | C39: =C38/C$8 -> 0.012986082 | D39: =D38/D$8 -> 0.012775133 | E39: =E38/E$8 -> 0.013424858 | F39: =CHOOSE($C$3,F40,F41,F42) -> 0.013 | G39: =CHOOSE($C$3,G40,G41,G42) -> 0.013 | H39: =CHOOSE($C$3,H40,H41,H42) -> 0.013 | I39: =CHOOSE($C$3,I40,I41,I42) -> 0.013
A40: Case 1 | F40: 0.013 | G40: 0.013 | H40: 0.013 | I40: 0.013
A41: Case 2 | F41: 0.014 | G41: 0.014 | H41: 0.014 | I41: 0.014
A42: Case 3 | F42: 0.015 | G42: 0.015 | H42: 0.015 | I42: 0.015
A44: Other expenses | C44: 1750.46 | D44: 2101.2 | E44: 2617.53 | F44: =F8*F45 -> 3094.6443 | G44: =G8*G45 -> 3651.6803 | H44: =H8*H45 -> 4272.466 | I44: =I8*I45 -> 4956.0605
A45: % of revenue | C45: =C44/C$8 -> 0.041843749 | D45: =D44/D$8 -> 0.042420248 | E45: =E44/E$8 -> 0.045293971 | F45: =CHOOSE($C$3,F46,F47,F48) -> 0.045 | G45: =CHOOSE($C$3,G46,G47,G48) -> 0.045 | H45: =CHOOSE($C$3,H46,H47,H48) -> 0.045 | I45: =CHOOSE($C$3,I46,I47,I48) -> 0.045
A46: Case 1 | F46: 0.045 | G46: 0.045 | H46: 0.045 | I46: 0.045
A47: Case 2 | F47: 0.048 | G47: 0.048 | H47: 0.048 | I47: 0.048
A48: Case 3 | F48: 0.052 | G48: 0.052 | H48: 0.052 | I48: 0.052
...

Sheet Expense Table
A1: Year | B1: COGS | C1: Employee Expense | D1: Finance Cost | E1: Depreciation | F1: Other Expenses
A2: FY23 | B2: ='P&L Assumptions'!C20 -> 35775.22 | C2: ='P&L Assumptions'!C26 -> 648.18 | D2: ='P&L Assumptions'!C32 -> 48.07 | E2: ='P&L Assumptions'!C38 -> 543.25 | F2: ='P&L Assumptions'!C44 -> 1750.46
A3: FY24 | B3: ='P&L Assumptions'!D20 -> 42546.65 | C3: ='P&L Assumptions'!D26 -> 785.71 | D3: ='P&L Assumptions'!D32 -> 44.27 | E3: ='P&L Assumptions'!D38 -> 632.79 | F3: ='P&L Assumptions'!D44 -> 2101.2
A4: FY25 | B4: ='P&L Assumptions'!E20 -> 49616.3 | C4: ='P&L Assumptions'!E26 -> 1013.26 | D4: ='P&L Assumptions'!E32 -> 57.75 | E4: ='P&L Assumptions'!E38 -> 775.82 | F4: ='P&L Assumptions'!E44 -> 2617.53
A5: FY26 Forecast | B5: ='P&L Assumptions'!F20 -> 58798.242 | C5: ='P&L Assumptions'!F26 -> 1237.8577 | D5: ='P&L Assumptions'!F32 -> 55.015899 | E5: ='P&L Assumptions'!F38 -> 894.00836 | F5: ='P&L Assumptions'!F44 -> 3094.6443
A6: FY27 Forecast | B6: ='P&L Assumptions'!G20 -> 69381.926 | C6: ='P&L Assumptions'!G26 -> 1460.6721 | D6: ='P&L Assumptions'!G32 -> 64.918761 | E6: ='P&L Assumptions'!G38 -> 1054.9299 | F6: ='P&L Assumptions'!G44 -> 3651.6803
A7: FY28 Forecast | B7: ='P&L Assumptions'!H20 -> 81176.853 | C7: ='P&L Assumptions'!H26 -> 1708.9864 | D7: ='P&L Assumptions'!H32 -> 75.95495 | E7: ='P&L Assumptions'!H38 -> 1234.2679 | F7: ='P&L Assumptions'!H44 -> 4272.466
A8: FY29 Forecast | B8: ='P&L Assumptions'!I20 -> 94165.15 | C8: ='P&L Assumptions'!I26 -> 1982.4242 | D8: ='P&L Assumptions'!I32 -> 88.107742 | E8: ='P&L Assumptions'!I38 -> 1431.7508 | F8: ='P&L Assumptions'!I44 -> 4956.0605
